<html>
<head>
<title>Détail de la correction.</title>
<style>
p.titre {font-weight: bold; font-family: Arial; font-size: 14pt;}
span.titreTest {font-weight: bold; font-family: Arial; font-size: 12pt; text-decoration: underline;}
span.verdictTest {font-family: Arial; font-size: 12pt;}
span.titreException {font-family: Arial; font-size: 12pt; text-decoration: underline;}
span.titreMessage {font-family: Arial; font-size: 12pt; text-decoration: underline;}
span.titrePileAppel {font-family: Arial; font-size: 12pt; text-decoration: underline;}
span.titreDiagnostic {font-family: Arial; font-size: 12pt; font-style: italic; color: #3300CC;}
span.pileAppel {font-family: Arial; font-size: 11pt;}
</style>
</head>
<body>
<p class="titre">Voici les tests qui ont posé des problèmes à votre exécutable. Cette liste est vide si tous se sont déroulés sans incident.</p>
<p><span class="titreTest">testDomainFindAllProductsInDogs(com.yaps.petstore.server.domain.h):</span> <span class="verdictTest">Votre exécutable a échoué en levant une exception.</span></p>
<p><span class="titreException">Exception levée:</span> java.lang.NullPointerException</p>
<p><span class="titrePileAppel">Pile d'appel:</span> <br><span class="pileAppel">java.lang.NullPointerException<br>	at com.yaps.petstore.server.domain.h.c(Unknown Source)<br>	at com.yaps.petstore.server.domain.h.setUp(Unknown Source)<br>	at junit.framework.TestCase.runBare(TestCase.java:132)<br>	at junit.framework.TestResult$1.protect(TestResult.java:110)<br>	at junit.framework.TestResult.runProtected(TestResult.java:128)<br>	at junit.framework.TestResult.run(TestResult.java:113)<br>	at junit.framework.TestCase.run(TestCase.java:124)<br>	at junit.framework.TestSuite.runTest(TestSuite.java:232)<br>	at junit.framework.TestSuite.run(TestSuite.java:227)<br>	at org.junit.internal.runners.JUnit38ClassRunner.run(JUnit38ClassRunner.java:81)<br>	at junit.framework.JUnit4TestAdapter.run(JUnit4TestAdapter.java:36)<br>	at junit.framework.TestSuite.runTest(TestSuite.java:232)<br>	at junit.framework.TestSuite.run(TestSuite.java:227)<br>	at junit.framework.TestSuite.runTest(TestSuite.java:232)<br>	at junit.framework.TestSuite.run(TestSuite.java:227)<br>	at B.tester(Unknown Source)<br>	at B.testerEtQuitter(Unknown Source)<br>	at Tests.main(Unknown Source)<br></span></p>
<p><span class="titreDiagnostic">testDomainFindAllProductsInDogs(com.yaps.petstore.server.domain.h): null</span></p>
<br>
<p><span class="titreTest">testRemove(com.yaps.petstore.server.domain.f):</span> <span class="verdictTest">Votre exécutable a échoué en levant une exception.</span></p>
<p><span class="titreException">Exception levée:</span> java.lang.IllegalStateException</p>
<p><span class="titreMessage">Message        :</span> Attempting to execute an operation on a closed EntityManager.</p>
<p><span class="titrePileAppel">Pile d'appel:</span> <br><span class="pileAppel">java.lang.IllegalStateException: Attempting to execute an operation on a closed EntityManager.<br>	at org.eclipse.persistence.internal.jpa.EntityManagerImpl.verifyOpen(EntityManagerImpl.java:1924)<br>	at org.eclipse.persistence.internal.jpa.transaction.EntityTransactionImpl.begin(EntityTransactionImpl.java:92)<br>	at com.yaps.petstore.server.domain.f.c(Unknown Source)<br>	at com.yaps.petstore.server.domain.f.setUp(Unknown Source)<br>	at junit.framework.TestCase.runBare(TestCase.java:132)<br>	at junit.framework.TestResult$1.protect(TestResult.java:110)<br>	at junit.framework.TestResult.runProtected(TestResult.java:128)<br>	at junit.framework.TestResult.run(TestResult.java:113)<br>	at junit.framework.TestCase.run(TestCase.java:124)<br>	at junit.framework.TestSuite.runTest(TestSuite.java:232)<br>	at junit.framework.TestSuite.run(TestSuite.java:227)<br>	at junit.framework.TestSuite.runTest(TestSuite.java:232)<br>	at junit.framework.TestSuite.run(TestSuite.java:227)<br>	at junit.framework.TestSuite.runTest(TestSuite.java:232)<br>	at junit.framework.TestSuite.run(TestSuite.java:227)<br>	at B.tester(Unknown Source)<br>	at B.testerEtQuitter(Unknown Source)<br>	at Tests.main(Unknown Source)<br></span></p>
<p><span class="titreDiagnostic">testRemove(com.yaps.petstore.server.domain.f): Attempting to execute an operation on a closed EntityManager.</span></p>
<br>
<p><span class="titreTest">testDetach(com.yaps.petstore.server.domain.f):</span> <span class="verdictTest">Votre exécutable a échoué en levant une exception.</span></p>
<p><span class="titreException">Exception levée:</span> java.lang.NullPointerException</p>
<p><span class="titrePileAppel">Pile d'appel:</span> <br><span class="pileAppel">java.lang.NullPointerException<br>	at com.yaps.petstore.server.domain.f.c(Unknown Source)<br>	at com.yaps.petstore.server.domain.f.setUp(Unknown Source)<br>	at junit.framework.TestCase.runBare(TestCase.java:132)<br>	at junit.framework.TestResult$1.protect(TestResult.java:110)<br>	at junit.framework.TestResult.runProtected(TestResult.java:128)<br>	at junit.framework.TestResult.run(TestResult.java:113)<br>	at junit.framework.TestCase.run(TestCase.java:124)<br>	at junit.framework.TestSuite.runTest(TestSuite.java:232)<br>	at junit.framework.TestSuite.run(TestSuite.java:227)<br>	at junit.framework.TestSuite.runTest(TestSuite.java:232)<br>	at junit.framework.TestSuite.run(TestSuite.java:227)<br>	at junit.framework.TestSuite.runTest(TestSuite.java:232)<br>	at junit.framework.TestSuite.run(TestSuite.java:227)<br>	at B.tester(Unknown Source)<br>	at B.testerEtQuitter(Unknown Source)<br>	at Tests.main(Unknown Source)<br></span></p>
<p><span class="titreDiagnostic">testDetach(com.yaps.petstore.server.domain.f): null</span></p>
<br>
<p><span class="titreTest">testUpdate(com.yaps.petstore.server.domain.f):</span> <span class="verdictTest">Votre exécutable a échoué en levant une exception.</span></p>
<p><span class="titreException">Exception levée:</span> java.lang.IllegalStateException</p>
<p><span class="titreMessage">Message        :</span> Attempting to execute an operation on a closed EntityManager.</p>
<p><span class="titrePileAppel">Pile d'appel:</span> <br><span class="pileAppel">java.lang.IllegalStateException: Attempting to execute an operation on a closed EntityManager.<br>	at org.eclipse.persistence.internal.jpa.EntityManagerImpl.verifyOpen(EntityManagerImpl.java:1924)<br>	at org.eclipse.persistence.internal.jpa.transaction.EntityTransactionImpl.begin(EntityTransactionImpl.java:92)<br>	at com.yaps.petstore.server.domain.f.c(Unknown Source)<br>	at com.yaps.petstore.server.domain.f.setUp(Unknown Source)<br>	at junit.framework.TestCase.runBare(TestCase.java:132)<br>	at junit.framework.TestResult$1.protect(TestResult.java:110)<br>	at junit.framework.TestResult.runProtected(TestResult.java:128)<br>	at junit.framework.TestResult.run(TestResult.java:113)<br>	at junit.framework.TestCase.run(TestCase.java:124)<br>	at junit.framework.TestSuite.runTest(TestSuite.java:232)<br>	at junit.framework.TestSuite.run(TestSuite.java:227)<br>	at junit.framework.TestSuite.runTest(TestSuite.java:232)<br>	at junit.framework.TestSuite.run(TestSuite.java:227)<br>	at junit.framework.TestSuite.runTest(TestSuite.java:232)<br>	at junit.framework.TestSuite.run(TestSuite.java:227)<br>	at B.tester(Unknown Source)<br>	at B.testerEtQuitter(Unknown Source)<br>	at Tests.main(Unknown Source)<br></span></p>
<p><span class="titreDiagnostic">testUpdate(com.yaps.petstore.server.domain.f): Attempting to execute an operation on a closed EntityManager.</span></p>
<br>
<p><span class="titreTest">testFfind(com.yaps.petstore.server.domain.f):</span> <span class="verdictTest">Votre exécutable a échoué en levant une exception.</span></p>
<p><span class="titreException">Exception levée:</span> java.lang.NullPointerException</p>
<p><span class="titrePileAppel">Pile d'appel:</span> <br><span class="pileAppel">java.lang.NullPointerException<br>	at com.yaps.petstore.server.domain.f.c(Unknown Source)<br>	at com.yaps.petstore.server.domain.f.setUp(Unknown Source)<br>	at junit.framework.TestCase.runBare(TestCase.java:132)<br>	at junit.framework.TestResult$1.protect(TestResult.java:110)<br>	at junit.framework.TestResult.runProtected(TestResult.java:128)<br>	at junit.framework.TestResult.run(TestResult.java:113)<br>	at junit.framework.TestCase.run(TestCase.java:124)<br>	at junit.framework.TestSuite.runTest(TestSuite.java:232)<br>	at junit.framework.TestSuite.run(TestSuite.java:227)<br>	at junit.framework.TestSuite.runTest(TestSuite.java:232)<br>	at junit.framework.TestSuite.run(TestSuite.java:227)<br>	at junit.framework.TestSuite.runTest(TestSuite.java:232)<br>	at junit.framework.TestSuite.run(TestSuite.java:227)<br>	at B.tester(Unknown Source)<br>	at B.testerEtQuitter(Unknown Source)<br>	at Tests.main(Unknown Source)<br></span></p>
<p><span class="titreDiagnostic">testFfind(com.yaps.petstore.server.domain.f): null</span></p>
<br>
<p><span class="titreTest">warning(junit.framework.TestSuite$1):</span> <span class="verdictTest">Le résultat que vous avez produit n'est pas celui attendu.</span></p>
<p><span class="titreDiagnostic">warning(junit.framework.TestSuite$1): Exception in constructor: testDomainUpdateOrder (javax.persistence.PersistenceException: Exception [EclipseLink-4002] (Eclipse Persistence Services - 2.6.1.v20150605-31e8258): org.eclipse.persistence.exceptions.DatabaseException
Internal Exception: java.sql.SQLException: Access denied for user 'root'@'localhost' (using password: NO)
Error Code: 1045
	at org.eclipse.persistence.internal.jpa.EntityManagerSetupImpl.deploy(EntityManagerSetupImpl.java:815)
	at org.eclipse.persistence.internal.jpa.EntityManagerFactoryDelegate.getAbstractSession(EntityManagerFactoryDelegate.java:205)
	at org.eclipse.persistence.internal.jpa.EntityManagerFactoryDelegate.createEntityManagerImpl(EntityManagerFactoryDelegate.java:305)
	at org.eclipse.persistence.internal.jpa.EntityManagerFactoryImpl.createEntityManagerImpl(EntityManagerFactoryImpl.java:337)
	at org.eclipse.persistence.internal.jpa.EntityManagerFactoryImpl.createEntityManager(EntityManagerFactoryImpl.java:303)
	at com.yaps.petstore.server.util.persistence.AbstractDataAccessObject.initEntityManager(Unknown Source)
	at com.yaps.petstore.server.util.persistence.AbstractDataAccessObject.<init>(Unknown Source)
	at com.yaps.petstore.server.domain.customer.CustomerDAO.<init>(Unknown Source)
	at com.yaps.petstore.server.domain.customer.CustomerDAO.<init>(Unknown Source)
	at com.yaps.petstore.server.domain.i.<init>(Unknown Source)
	at sun.reflect.NativeConstructorAccessorImpl.newInstance0(Native Method)
	at sun.reflect.NativeConstructorAccessorImpl.newInstance(NativeConstructorAccessorImpl.java:62)
	at sun.reflect.DelegatingConstructorAccessorImpl.newInstance(DelegatingConstructorAccessorImpl.java:45)
	at java.lang.reflect.Constructor.newInstance(Constructor.java:422)
	at junit.framework.TestSuite.createTest(TestSuite.java:65)
	at junit.framework.TestSuite.addTestMethod(TestSuite.java:283)
	at junit.framework.TestSuite.<init>(TestSuite.java:146)
	at com.yaps.petstore.server.domain.i.suite(Unknown Source)
	at AllDomainTests.suite(Unknown Source)
	at AllTests.suite(Unknown Source)
	at Tests.main(Unknown Source)
Caused by: Exception [EclipseLink-4002] (Eclipse Persistence Services - 2.6.1.v20150605-31e8258): org.eclipse.persistence.exceptions.DatabaseException
Internal Exception: java.sql.SQLException: Access denied for user 'root'@'localhost' (using password: NO)
Error Code: 1045
	at org.eclipse.persistence.exceptions.DatabaseException.sqlException(DatabaseException.java:331)
	at org.eclipse.persistence.exceptions.DatabaseException.sqlException(DatabaseException.java:326)
	at org.eclipse.persistence.sessions.DefaultConnector.connect(DefaultConnector.java:138)
	at org.eclipse.persistence.sessions.DatasourceLogin.connectToDatasource(DatasourceLogin.java:162)
	at org.eclipse.persistence.internal.databaseaccess.DatasourceAccessor.connectInternal(DatasourceAccessor.java:346)
	at org.eclipse.persistence.internal.databaseaccess.DatabaseAccessor.connectInternal(DatabaseAccessor.java:309)
	at org.eclipse.persistence.internal.databaseaccess.DatasourceAccessor.connect(DatasourceAccessor.java:434)
	at org.eclipse.persistence.sessions.server.ConnectionPool.buildConnection(ConnectionPool.java:217)
	at org.eclipse.persistence.sessions.server.ConnectionPool.startUp(ConnectionPool.java:505)
	at org.eclipse.persistence.sessions.server.ServerSession.connect(ServerSession.java:488)
	at org.eclipse.persistence.internal.sessions.DatabaseSessionImpl.login(DatabaseSessionImpl.java:764)
	at org.eclipse.persistence.internal.jpa.EntityManagerFactoryProvider.login(EntityManagerFactoryProvider.java:267)
	at org.eclipse.persistence.internal.jpa.EntityManagerSetupImpl.deploy(EntityManagerSetupImpl.java:731)
	... 20 more
Caused by: java.sql.SQLException: Access denied for user 'root'@'localhost' (using password: NO)
	at com.mysql.jdbc.SQLError.createSQLException(SQLError.java:1074)
	at com.mysql.jdbc.MysqlIO.checkErrorPacket(MysqlIO.java:4074)
	at com.mysql.jdbc.MysqlIO.checkErrorPacket(MysqlIO.java:4006)
	at com.mysql.jdbc.MysqlIO.checkErrorPacket(MysqlIO.java:919)
	at com.mysql.jdbc.MysqlIO.proceedHandshakeWithPluggableAuthentication(MysqlIO.java:1694)
	at com.mysql.jdbc.MysqlIO.doHandshake(MysqlIO.java:1244)
	at com.mysql.jdbc.ConnectionImpl.coreConnect(ConnectionImpl.java:2397)
	at com.mysql.jdbc.ConnectionImpl.connectOneTryOnly(ConnectionImpl.java:2430)
	at com.mysql.jdbc.ConnectionImpl.createNewIO(ConnectionImpl.java:2215)
	at com.mysql.jdbc.ConnectionImpl.<init>(ConnectionImpl.java:813)
	at com.mysql.jdbc.JDBC4Connection.<init>(JDBC4Connection.java:47)
	at sun.reflect.GeneratedConstructorAccessor9.newInstance(Unknown Source)
	at sun.reflect.DelegatingConstructorAccessorImpl.newInstance(DelegatingConstructorAccessorImpl.java:45)
	at java.lang.reflect.Constructor.newInstance(Constructor.java:422)
	at com.mysql.jdbc.Util.handleNewInstance(Util.java:411)
	at com.mysql.jdbc.ConnectionImpl.getInstance(ConnectionImpl.java:399)
	at com.mysql.jdbc.NonRegisteringDriver.connect(NonRegisteringDriver.java:334)
	at java.sql.DriverManager.getConnection(DriverManager.java:664)
	at java.sql.DriverManager.getConnection(DriverManager.java:208)
	at org.eclipse.persistence.sessions.DefaultConnector.connect(DefaultConnector.java:98)
	... 30 more
)</span></p>
<br>
<p><span class="titreTest">testDomainFindAllProducts(com.yaps.petstore.server.domain.h):</span> <span class="verdictTest">Votre exécutable a échoué en levant une exception.</span></p>
<p><span class="titreException">Exception levée:</span> java.lang.NullPointerException</p>
<p><span class="titrePileAppel">Pile d'appel:</span> <br><span class="pileAppel">java.lang.NullPointerException<br>	at com.yaps.petstore.server.domain.h.c(Unknown Source)<br>	at com.yaps.petstore.server.domain.h.setUp(Unknown Source)<br>	at junit.framework.TestCase.runBare(TestCase.java:132)<br>	at junit.framework.TestResult$1.protect(TestResult.java:110)<br>	at junit.framework.TestResult.runProtected(TestResult.java:128)<br>	at junit.framework.TestResult.run(TestResult.java:113)<br>	at junit.framework.TestCase.run(TestCase.java:124)<br>	at junit.framework.TestSuite.runTest(TestSuite.java:232)<br>	at junit.framework.TestSuite.run(TestSuite.java:227)<br>	at org.junit.internal.runners.JUnit38ClassRunner.run(JUnit38ClassRunner.java:81)<br>	at junit.framework.JUnit4TestAdapter.run(JUnit4TestAdapter.java:36)<br>	at junit.framework.TestSuite.runTest(TestSuite.java:232)<br>	at junit.framework.TestSuite.run(TestSuite.java:227)<br>	at junit.framework.TestSuite.runTest(TestSuite.java:232)<br>	at junit.framework.TestSuite.run(TestSuite.java:227)<br>	at B.tester(Unknown Source)<br>	at B.testerEtQuitter(Unknown Source)<br>	at Tests.main(Unknown Source)<br></span></p>
<p><span class="titreDiagnostic">testDomainFindAllProducts(com.yaps.petstore.server.domain.h): null</span></p>
<br>
<p><span class="titreTest">testRefresh(com.yaps.petstore.server.domain.f):</span> <span class="verdictTest">Votre exécutable a échoué en levant une exception.</span></p>
<p><span class="titreException">Exception levée:</span> java.lang.IllegalStateException</p>
<p><span class="titreMessage">Message        :</span> Attempting to execute an operation on a closed EntityManager.</p>
<p><span class="titrePileAppel">Pile d'appel:</span> <br><span class="pileAppel">java.lang.IllegalStateException: Attempting to execute an operation on a closed EntityManager.<br>	at org.eclipse.persistence.internal.jpa.EntityManagerImpl.verifyOpen(EntityManagerImpl.java:1924)<br>	at org.eclipse.persistence.internal.jpa.transaction.EntityTransactionImpl.begin(EntityTransactionImpl.java:92)<br>	at com.yaps.petstore.server.domain.f.c(Unknown Source)<br>	at com.yaps.petstore.server.domain.f.setUp(Unknown Source)<br>	at junit.framework.TestCase.runBare(TestCase.java:132)<br>	at junit.framework.TestResult$1.protect(TestResult.java:110)<br>	at junit.framework.TestResult.runProtected(TestResult.java:128)<br>	at junit.framework.TestResult.run(TestResult.java:113)<br>	at junit.framework.TestCase.run(TestCase.java:124)<br>	at junit.framework.TestSuite.runTest(TestSuite.java:232)<br>	at junit.framework.TestSuite.run(TestSuite.java:227)<br>	at junit.framework.TestSuite.runTest(TestSuite.java:232)<br>	at junit.framework.TestSuite.run(TestSuite.java:227)<br>	at junit.framework.TestSuite.runTest(TestSuite.java:232)<br>	at junit.framework.TestSuite.run(TestSuite.java:227)<br>	at B.tester(Unknown Source)<br>	at B.testerEtQuitter(Unknown Source)<br>	at Tests.main(Unknown Source)<br></span></p>
<p><span class="titreDiagnostic">testRefresh(com.yaps.petstore.server.domain.f): Attempting to execute an operation on a closed EntityManager.</span></p>
<br>
<p><span class="titreTest">testDomainDeleteUnknownCustomer(com.yaps.petstore.server.domain.b):</span> <span class="verdictTest">Votre exécutable a échoué en levant une exception.</span></p>
<p><span class="titreException">Exception levée:</span> javax.persistence.PersistenceException</p>
<p><span class="titreMessage">Message        :</span> Exception [EclipseLink-4002] (Eclipse Persistence Services - 2.6.1.v20150605-31e8258): org.eclipse.persistence.exceptions.DatabaseException
Internal Exception: java.sql.SQLException: Access denied for user 'root'@'localhost' (using password: NO)
Error Code: 1045</p>
<p><span class="titrePileAppel">Pile d'appel:</span> <br><span class="pileAppel">javax.persistence.PersistenceException: Exception [EclipseLink-4002] (Eclipse Persistence Services - 2.6.1.v20150605-31e8258): org.eclipse.persistence.exceptions.DatabaseException<br>Internal Exception: java.sql.SQLException: Access denied for user 'root'@'localhost' (using password: NO)<br>Error Code: 1045<br>	at org.eclipse.persistence.internal.jpa.EntityManagerSetupImpl.deploy(EntityManagerSetupImpl.java:815)<br>	at org.eclipse.persistence.internal.jpa.EntityManagerFactoryDelegate.getAbstractSession(EntityManagerFactoryDelegate.java:205)<br>	at org.eclipse.persistence.internal.jpa.EntityManagerFactoryDelegate.createEntityManagerImpl(EntityManagerFactoryDelegate.java:305)<br>	at org.eclipse.persistence.internal.jpa.EntityManagerFactoryImpl.createEntityManagerImpl(EntityManagerFactoryImpl.java:337)<br>	at org.eclipse.persistence.internal.jpa.EntityManagerFactoryImpl.createEntityManager(EntityManagerFactoryImpl.java:303)<br>	at com.yaps.petstore.server.util.persistence.AbstractDataAccessObject.initEntityManager(Unknown Source)<br>	at com.yaps.petstore.server.util.persistence.AbstractDataAccessObject.<init>(Unknown Source)<br>	at com.yaps.petstore.server.util.uidgen.UniqueIdGeneratorDAO.<init>(Unknown Source)<br>	at com.yaps.petstore.server.util.uidgen.UniqueIdGeneratorDAO.<init>(Unknown Source)<br>	at com.yaps.petstore.server.util.uidgen.UniqueIdGenerator.<init>(Unknown Source)<br>	at com.yaps.petstore.server.util.uidgen.UniqueIdGenerator.getInstance(Unknown Source)<br>	at com.yaps.petstore.server.util.persistence.AbstractDataAccessObject.getUniqueId(Unknown Source)<br>	at com.yaps.petstore.server.domain.b.b(Unknown Source)<br>	at com.yaps.petstore.server.domain.b.testDomainDeleteUnknownCustomer(Unknown Source)<br>	at sun.reflect.NativeMethodAccessorImpl.invoke0(Native Method)<br>	at sun.reflect.NativeMethodAccessorImpl.invoke(NativeMethodAccessorImpl.java:62)<br>	at sun.reflect.DelegatingMethodAccessorImpl.invoke(DelegatingMethodAccessorImpl.java:43)<br>	at java.lang.reflect.Method.invoke(Method.java:497)<br>	at junit.framework.TestCase.runTest(TestCase.java:168)<br>	at junit.framework.TestCase.runBare(TestCase.java:134)<br>	at junit.framework.TestResult$1.protect(TestResult.java:110)<br>	at junit.framework.TestResult.runProtected(TestResult.java:128)<br>	at junit.framework.TestResult.run(TestResult.java:113)<br>	at junit.framework.TestCase.run(TestCase.java:124)<br>	at junit.framework.TestSuite.runTest(TestSuite.java:232)<br>	at junit.framework.TestSuite.run(TestSuite.java:227)<br>	at junit.framework.TestSuite.runTest(TestSuite.java:232)<br>	at junit.framework.TestSuite.run(TestSuite.java:227)<br>	at junit.framework.TestSuite.runTest(TestSuite.java:232)<br>	at junit.framework.TestSuite.run(TestSuite.java:227)<br>	at B.tester(Unknown Source)<br>	at B.testerEtQuitter(Unknown Source)<br>	at Tests.main(Unknown Source)<br>Caused by: Exception [EclipseLink-4002] (Eclipse Persistence Services - 2.6.1.v20150605-31e8258): org.eclipse.persistence.exceptions.DatabaseException<br>Internal Exception: java.sql.SQLException: Access denied for user 'root'@'localhost' (using password: NO)<br>Error Code: 1045<br>	at org.eclipse.persistence.exceptions.DatabaseException.sqlException(DatabaseException.java:331)<br>	at org.eclipse.persistence.exceptions.DatabaseException.sqlException(DatabaseException.java:326)<br>	at org.eclipse.persistence.sessions.DefaultConnector.connect(DefaultConnector.java:138)<br>	at org.eclipse.persistence.sessions.DatasourceLogin.connectToDatasource(DatasourceLogin.java:162)<br>	at org.eclipse.persistence.internal.databaseaccess.DatasourceAccessor.connectInternal(DatasourceAccessor.java:346)<br>	at org.eclipse.persistence.internal.databaseaccess.DatabaseAccessor.connectInternal(DatabaseAccessor.java:309)<br>	at org.eclipse.persistence.internal.databaseaccess.DatasourceAccessor.connect(DatasourceAccessor.java:434)<br>	at org.eclipse.persistence.sessions.server.ConnectionPool.buildConnection(ConnectionPool.java:217)<br>	at org.eclipse.persistence.sessions.server.ConnectionPool.startUp(ConnectionPool.java:505)<br>	at org.eclipse.persistence.sessions.server.ServerSession.connect(ServerSession.java:488)<br>	at org.eclipse.persistence.internal.sessions.DatabaseSessionImpl.login(DatabaseSessionImpl.java:764)<br>	at org.eclipse.persistence.internal.jpa.EntityManagerFactoryProvider.login(EntityManagerFactoryProvider.java:267)<br>	at org.eclipse.persistence.internal.jpa.EntityManagerSetupImpl.deploy(EntityManagerSetupImpl.java:731)<br>	... 32 more<br>Caused by: java.sql.SQLException: Access denied for user 'root'@'localhost' (using password: NO)<br>	at com.mysql.jdbc.SQLError.createSQLException(SQLError.java:1074)<br>	at com.mysql.jdbc.MysqlIO.checkErrorPacket(MysqlIO.java:4074)<br>	at com.mysql.jdbc.MysqlIO.checkErrorPacket(MysqlIO.java:4006)<br>	at com.mysql.jdbc.MysqlIO.checkErrorPacket(MysqlIO.java:919)<br>	at com.mysql.jdbc.MysqlIO.proceedHandshakeWithPluggableAuthentication(MysqlIO.java:1694)<br>	at com.mysql.jdbc.MysqlIO.doHandshake(MysqlIO.java:1244)<br>	at com.mysql.jdbc.ConnectionImpl.coreConnect(ConnectionImpl.java:2397)<br>	at com.mysql.jdbc.ConnectionImpl.connectOneTryOnly(ConnectionImpl.java:2430)<br>	at com.mysql.jdbc.ConnectionImpl.createNewIO(ConnectionImpl.java:2215)<br>	at com.mysql.jdbc.ConnectionImpl.<init>(ConnectionImpl.java:813)<br>	at com.mysql.jdbc.JDBC4Connection.<init>(JDBC4Connection.java:47)<br>	at sun.reflect.GeneratedConstructorAccessor9.newInstance(Unknown Source)<br>	at sun.reflect.DelegatingConstructorAccessorImpl.newInstance(DelegatingConstructorAccessorImpl.java:45)<br>	at java.lang.reflect.Constructor.newInstance(Constructor.java:422)<br>	at com.mysql.jdbc.Util.handleNewInstance(Util.java:411)<br>	at com.mysql.jdbc.ConnectionImpl.getInstance(ConnectionImpl.java:399)<br>	at com.mysql.jdbc.NonRegisteringDriver.connect(NonRegisteringDriver.java:334)<br>	at java.sql.DriverManager.getConnection(DriverManager.java:664)<br>	at java.sql.DriverManager.getConnection(DriverManager.java:208)<br>	at org.eclipse.persistence.sessions.DefaultConnector.connect(DefaultConnector.java:98)<br>	... 42 more<br></span></p>
<p><span class="titreDiagnostic">testDomainDeleteUnknownCustomer(com.yaps.petstore.server.domain.b): Exception [EclipseLink-4002] (Eclipse Persistence Services - 2.6.1.v20150605-31e8258): org.eclipse.persistence.exceptions.DatabaseException
Internal Exception: java.sql.SQLException: Access denied for user 'root'@'localhost' (using password: NO)
Error Code: 1045</span></p>
<br>
</body>
</html>
